Workbook

Sheet SUMMARY
B2: PLANT & CML,TP
B3: DETAILS SUMMARY OF NO. OF UNITS MFGD IN APR-2022 (QTY.IN LACS) | L3: =TODAY() -> 44727
B4: Sr.No | C4: Material Class | D4: PTN | E4: DHJ | F4: GHT | G4: PMR | H4: CTGN | I4: CKT | J4: CML | K4: TP | L4: Total
B5: 1 | C5: Ampoule | D5: 0 | E5: 0 | F5: 0 | G5: 0 | H5: 0 | I5: 0 | J5: 0 | K5: =TP!L6/100000 -> 0.6 | L5: =SUM(D5:K5) -> 0.6
B6: 2 | C6: Capsules | D6: =PTN!L20/100000 -> 323.61098 | E6: =DHJ!L44/100000 -> 442.77866 | F6: =GHT!L15/100000 -> 44.00925 | G6: =PMR!L9/100000 -> 16.25514 | H6: =CTGN!L6/100000 -> 4.8111 | I6: =CKT!L9/100000 -> 25.627 | J6: =CML!L8/100000 -> 12.696 | K6: =TP!L21/100000 -> 61.59372 | L6: =SUM(D6:K6) -> 931.38185
B7: 3 | C7: Dry Syrup/Granules | D7: 0 | E7: =DHJ!L64/100000 -> 12.55682 | F7: =GHT!L68/100000 -> 1.23149 | G7: 0 | H7: =CTGN!L17/100000 -> 1.9545 | I7: 0 | J7: =CML!L51/100000 -> 6.008 | K7: 0 | L7: =SUM(D7:K7) -> 21.75081
B8: 4 | C8: Eye Drops | D8: 0 | E8: 0 | F8: =GHT!L101/100000 -> 8.87255 | G8: 0 | H8: 0 | I8: 0 | J8: =CML!L97/100000 -> 9.01035 | K8: =TP!L30/100000 -> 0.15425 | L8: =SUM(D8:K8) -> 18.03715
B9: 5 | C9: Face Wash | D9: 0 | E9: 0 | F9: =GHT!L105/100000 -> 0.14793 | G9: 0 | H9: 0 | I9: 0 | J9: 0 | K9: =TP!L34/100000 -> 0.14118 | L9: =SUM(D9:K9) -> 0.28911
B10: 6 | C10: Gel | D10: 0 | E10: 0 | F10: 0 | G10: 0 | H10: 0 | I10: 0 | J10: 0 | K10: =TP!L37/100000 -> 0.18132 | L10: =SUM(D10:K10) -> 0.18132
B11: 7 | C11: Hair Serum | D11: 0 | E11: 0 | F11: 0 | G11: 0 | H11: 0 | I11: 0 | J11: 0 | K11: 0 | L11: =SUM(D11:K11) -> 0
B12: 8 | C12: Injection | D12: 0 | E12: 0 | F12: 0 | G12: 0 | H12: 0 | I12: 0 | J12: =CML!L100/100000 -> 0.924 | K12: 0 | L12: =SUM(D12:K12) -> 0.924
B13: 9 | C13: Jelly | D13: 0 | E13: 0 | F13: =GHT!L108/100000 -> 6.30427 | G13: 0 | H13: =CTGN!L27/100000 -> 10.62725 | I13: 0 | J13: 0 | K13: 0 | L13: =SUM(D13:K13) -> 16.93152
B14: 10 | C14: Kit | D14: =PTN!L22/100000 -> 0.02524 | E14: 0 | F14: 0 | G14: 0 | H14: 0 | I14: 0 | J14: 0 | K14: 0 | L14: =SUM(D14:K14) -> 0.02524
B15: 11 | C15: Liquid/Lotion/Syrup | D15: 0 | E15: 0 | F15: =GHT!L111/100000 -> 0.1647 | G15: 0 | H15: 0 | I15: =CKT!L35/100000 -> 7.6723 | J15: =CML!L107/100000+CML!L170/100000 -> 4.36678 | K15: =TP!L50/100000 -> 0.46145 | L15: =SUM(D15:K15) -> 12.66523
B16: 12 | C16: Lozenges | D16: 0 | E16: 0 | F16: 0 | G16: 0 | H16: 0 | I16: 0 | J16: 0 | K16: =TP!L39/100000 -> 5.536 | L16: =SUM(D16:K16) -> 5.536
B17: 13 | C17: Mouthwash | D17: 0 | E17: 0 | F17: 0 | G17: 0 | H17: 0 | I17: 0 | J17: 0 | K17: 0 | L17: =SUM(D17:K17) -> 0
B18: 14 | C18: Ointment/Cream | D18: 0 | E18: 0 | F18: =GHT!L49/100000 -> 7.05273 | G18: 0 | H18: 0 | I18: 0 | J18: =CML!L25/100000 -> 2.23499 | K18: =TP!L27/100000 -> 0.65725 | L18: =SUM(D18:K18) -> 9.94497
B19: 15 | C19: Oral Solution | D19: 0 | E19: 0 | F19: 0 | G19: 0 | H19: 0 | I19: 0 | J19: 0 | K19: 0 | L19: =SUM(D19:K19) -> 0
B20: 16 | C20: ORS/Powder | D20: 0 | E20: 0 | F20: 0 | G20: 0 | H20: 0 | I20: 0 | J20: 0 | K20: =TP!L42/100000 -> 0.96768 | L20: =SUM(D20:K20) -> 0.96768
B21: 17 | C21: Shampoo | D21: 0 | E21: 0 | F21: 0 | G21: 0 | H21: 0 | I21: 0 | J21: =CML!L132/100000 -> 3.04115 | K21: 0 | L21: =SUM(D21:K21) -> 3.04115
B22: 18 | C22: Soap | D22: 0 | E22: 0 | F22: 0 | G22: 0 | H22: 0 | I22: 0 | J22: =CML!L143/100000 -> 1.4401 | K22: 0 | L22: =SUM(D22:K22) -> 1.4401
B23: 19 | C23: Soft Gel Cap | D23: 0 | E23: 0 | F23: 0 | G23: 0 | H23: 0 | I23: 0 | J23: 0 | K23: 0 | L23: =SUM(D23:K23) -> 0
B24: 20 | C24: Tablets | D24: =PTN!L124/100000 -> 852.99575 | E24: =DHJ!L160/100000 -> 1090.0452 | F24: =GHT!L209/100000 -> 820.47376 | G24: =PMR!L49/100000 -> 157.64129 | H24: =CTGN!L84/100000 -> 186.78203 | I24: 0 | J24: =CML!L213/100000 -> 137.3872 | K24: =TP!L76/100000 -> 61.4878 | L24: =SUM(D24:K24) -> 3306.813
C25: Total | D25: =SUM(D5:D24) -> 1176.632 | E25: =SUM(E5:E24) -> 1545.3807 | F25: =SUM(F5:F24) -> 888.25668 | G25: =SUM(G5:G24) -> 173.89643 | H25: =SUM(H5:H24) -> 204.17488 | I25: =SUM(I5:I24) -> 33.2993 | J25: =SUM(J5:J24) -> 177.10857 | K25: =SUM(K5:K24) -> 131.78065 | L25: =SUM(L5:L24) -> 4330.5291
B28: Sr.No | C28: Material Class | D28: PTN | E28: DHJ | F28: GHT | G28: PMR | H28: CTGN | I28: CKT | J28: CML | K28: TP | L28: Total
B29: 1 | C29: Ampoule | D29: =D5/100 -> 0 | E29: =E5/100 -> 0 | F29: =F5/100 -> 0 | G29: =G5/100 -> 0 | H29: =H5/100 -> 0 | I29: =I5/100 -> 0 | J29: =J5/100 -> 0 | K29: =K5/100 -> 0.006 | L29: =SUM(D29:K29) -> 0.006
B30: 2 | C30: Capsules | D30: =D6/100 -> 3.2361098 | E30: =E6/100 -> 4.4277866 | F30: =F6/100 -> 0.4400925 | G30: =G6/100 -> 0.1625514 | H30: =H6/100 -> 0.048111 | I30: =I6/100 -> 0.25627 | J30: =J6/100 -> 0.12696 | K30: =K6/100 -> 0.6159372 | L30: =SUM(D30:K30) -> 9.3138185
B31: 3 | C31: Dry Syrup/Granules | D31: =D7/100 -> 0 | E31: =E7/100 -> 0.1255682 | F31: =F7/100 -> 0.0123149 | G31: =G7/100 -> 0 | H31: =H7/100 -> 0.019545 | I31: =I7/100 -> 0 | J31: =J7/100 -> 0.06008 | K31: =K7/100 -> 0 | L31: =SUM(D31:K31) -> 0.2175081
B32: 4 | C32: Eye Drops | D32: =D8/100 -> 0 | E32: =E8/100 -> 0 | F32: =F8/100 -> 0.0887255 | G32: =G8/100 -> 0 | H32: =H8/100 -> 0 | I32: =I8/100 -> 0 | J32: =J8/100 -> 0.0901035 | K32: =K8/100 -> 0.0015425 | L32: =SUM(D32:K32) -> 0.1803715
B33: 5 | C33: Face Wash | D33: =D9/100 -> 0 | E33: =E9/100 -> 0 | F33: =F9/100 -> 0.0014793 | G33: =G9/100 -> 0 | H33: =H9/100 -> 0 | I33: =I9/100 -> 0 | J33: =J9/100 -> 0 | K33: =K9/100 -> 0.0014118 | L33: =SUM(D33:K33) -> 0.0028911
B34: 6 | C34: Gel | D34: =D10/100 -> 0 | E34: =E10/100 -> 0 | F34: =F10/100 -> 0 | G34: =G10/100 -> 0 | H34: =H10/100 -> 0 | I34: =I10/100 -> 0 | J34: =J10/100 -> 0 | K34: =K10/100 -> 0.0018132 | L34: =SUM(D34:K34) -> 0.0018132
B35: 7 | C35: Hair Serum | D35: =D11/100 -> 0 | E35: =E11/100 -> 0 | F35: =F11/100 -> 0 | G35: =G11/100 -> 0 | H35: =H11/100 -> 0 | I35: =I11/100 -> 0 | J35: =J11/100 -> 0 | K35: =K11/100 -> 0 | L35: =SUM(D35:K35) -> 0
B36: 8 | C36: Injection | D36: =D12/100 -> 0 | E36: =E12/100 -> 0 | F36: =F12/100 -> 0 | G36: =G12/100 -> 0 | H36: =H12/100 -> 0 | I36: =I12/100 -> 0 | J36: =J12/100 -> 0.00924 | K36: =K12/100 -> 0 | L36: =SUM(D36:K36) -> 0.00924
B37: 9 | C37: Jelly | D37: =D13/100 -> 0 | E37: =E13/100 -> 0 | F37: =F13/100 -> 0.0630427 | G37: =G13/100 -> 0 | H37: =H13/100 -> 0.1062725 | I37: =I13/100 -> 0 | J37: =J13/100 -> 0 | K37: =K13/100 -> 0 | L37: =SUM(D37:K37) -> 0.1693152
B38: 10 | C38: Kit | D38: =D14/100 -> 0.0002524 | E38: =E14/100 -> 0 | F38: =F14/100 -> 0 | G38: =G14/100 -> 0 | H38: =H14/100 -> 0 | I38: =I14/100 -> 0 | J38: =J14/100 -> 0 | K38: =K14/100 -> 0 | L38: =SUM(D38:K38) -> 0.0002524
B39: 11 | C39: Liquid/Lotion/Syrup | D39: =D15/100 -> 0 | E39: =E15/100 -> 0 | F39: =F15/100 -> 0.001647 | G39: =G15/100 -> 0 | H39: =H15/100 -> 0 | I39: =I15/100 -> 0.076723 | J39: =J15/100 -> 0.0436678 | K39: =K15/100 -> 0.0046145 | L39: =SUM(D39:K39) -> 0.1266523
B40: 12 | C40: Lozenges | D40: =D16/100 -> 0 | E40: =E16/100 -> 0 | F40: =F16/100 -> 0 | G40: =G16/100 -> 0 | H40: =H16/100 -> 0 | I40: =I16/100 -> 0 | J40: =J16/100 -> 0 | K40: =K16/100 -> 0.05536 | L40: =SUM(D40:K40) -> 0.05536
... B48: 20 | C48: Tablets | D48: =D24/100 -> 8.5299575 | E48: =E24/100 -> 10.900452 | F48: =F24/100 -> 8.2047376 | G48: =G24/100 -> 1.5764129 | H48: =H24/100 -> 1.8678203 | I48: =I24/100 -> 0 | J48: =J24/100 -> 1.373872 | K48: =K24/100 -> 0.614878 | L48: =SUM(D48:K48) -> 33.06813
C49: Total | D49: =SUM(D29:D48) -> 11.76632 | E49: =SUM(E29:E48) -> 15.453807 | F49: =SUM(F29:F48) -> 8.8825668 | G49: =SUM(G29:G48) -> 1.7389643 | H49: =SUM(H29:H48) -> 2.0417488 | I49: =SUM(I29:I48) -> 0.332993 | J49: =SUM(J29:J48) -> 1.7710857 | K49: =SUM(K29:K48) -> 1.3178065 | L49: =SUM(L29:L48) -> 43.305291

Sheet Sum
B2: Summary of VOP for the month of April 2022
D3: Rs. Lacs
B4: Location | C4: DPCO | D4: VOP | E4: %
B6: Paithan | C6: =+PTN!N126/10^5 -> 52.749724 | D6: =+PTN!P126/10^5 -> 4121.4131 | E6: =+D6/$D$15 -> 0.16444185 | G6: =D6/100 -> 41.214131
B7: Dahej | C7: =+DHJ!N162/10^5 -> 76.34046 | D7: =+DHJ!P162/10^5 -> 4232.058 | E7: =+D7/$D$15 -> 0.16885651 | G7: =D7/100 -> 42.32058
B8: Guwahati | C8: =+GHT!N211/10^5 -> 57.59001 | D8: =+GHT!P211/10^5 -> 7165.9409 | E8: =+D8/$D$15 -> 0.28591663 | G8: =D8/100 -> 71.659409
B9: Pithampur | C9: =+PMR!N51/10^5 -> 8.513499 | D9: =+PMR!P51/10^5 -> 1506.2002 | E9: =+D9/$D$15 -> 0.06009646 | G9: =D9/100 -> 15.062002
B10: Chitegaon | C10: =+CTGN!N86/10^5 -> 17.787394 | D10: =+CTGN!P86/10^5 -> 1614.8026 | E10: =+D10/$D$15 -> 0.06442963 | G10: =D10/100 -> 16.148026
B11: Chikalthana | C11: =+CKT!N37/10^5 -> 13.359806 | D11: =+CKT!P37/10^5 -> 556.96956 | E11: =+D11/$D$15 -> 0.022222743 | G11: =D11/100 -> 5.5696956
B12: Contract Manufacturing | C12: =+CML!N215/10^5 -> 50.422464 | D12: =+CML!P215/10^5 -> 4221.9634 | E12: =+D12/$D$15 -> 0.16845374 | G12: =D12/100 -> 42.219634
B13: Third Party | D13: =+TP!P78/10^5 -> 1643.6954 | E13: =+D13/$D$15 -> 0.065582434 | G13: =D13/100 -> 16.436954
B15: Total (Rs. Lacs) | C15: =SUM(C6:C14) -> 276.76336 | D15: =SUM(D6:D14) -> 25063.043 | E15: =SUM(E6:E14) -> 1

Sheet PTN
B2: PAITHAN PLANT
B3: PRODUCTION DETAILS FOR THE MONTH OF APR-2022
B4: Sr. No. | C4: Plant | D4: Material code | E4: Material description | F4: Material Group | G4: Material Class | H4: Batch No | I4: Pack size | J4: Unit | K4: Prodn. Qty. in packs | L4: Qty. in Nos. | M4: DPCO Rate | N4: DPCO Value | O4: VOP Rate | P4: VOP
B5: 1 | C5: 1010 | D5: 5001213 | E5: DULOXETINE DR CAP 30MG,USA,90 | F5: FG-ANDA | G5: Z_CAPSULE | H5: PA06952 | I5: 90 | J5: BT | K5: 53937 | L5: =K5*I5 -> 4854330 | M5: 6.2398969 | N5: =+K5*M5 -> 336561.32 | O5: 144.001 | P5: =+K5*O5 -> 7766981.9
B6: 2 | C6: 1010 | D6: 5001041 | E6: FEDATE CAP,FA,3X10 | F6: FG-ROW | G6: Z_CAPSULE | H6: PA03592 | I6: 10 | J6: Bl | K6: 38613 | L6: =K6*I6 -> 386130 | M6: 0.74520408 | N6: =+K6*M6 -> 28774.565 | O6: 47.1436 | P6: =+K6*O6 -> 1820355.8
B7: 3 | C7: 1010 | D7: 5001212 | E7: DULOXETINE DR CAP 30MG,USA,30 | F7: FG-ANDA | G7: Z_CAPSULE | H7: PA06942 | I7: 30 | J7: BT | K7: 157468 | L7: =K7*I7 -> 4724040 | M7: 2.5473196 | N7: =+K7*M7 -> 401121.32 | O7: 60.42 | P7: =+K7*O7 -> 9514216.6
B8: 4 | C8: 1010 | D8: 5001212 | E8: DULOXETINE DR CAP 30MG,USA,30 | F8: FG-ANDA | G8: Z_CAPSULE | H8: PA06932 | I8: 30 | J8: BT | K8: 160300 | L8: =K8*I8 -> 4809000 | M8: 2.5473196 | N8: =+K8*M8 -> 408335.33 | O8: 60.42 | P8: =+K8*O8 -> 9685326
B9: 5 | C9: 1010 | D9: 5001211 | E9: DULOXETINE DR CAP 20MG,USA,60 | F9: FG-ANDA | G9: Z_CAPSULE | H9: PA06922 | I9: 60 | J9: BT | K9: 116262 | L9: =K9*I9 -> 6975720 | M9: 4.5222449 | N9: =+K9*M9 -> 525765.24 | O9: 67.05 | P9: =+K9*O9 -> 7795367.1
B10: 6 | C10: 1010 | D10: 5006583 | E10: FEDATE CAP,UGA/TZA,3X10'S | F10: FG-ROW | G10: Z_CAPSULE | H10: PA03592 | I10: 10 | J10: Bl | K10: 29805 | L10: =K10*I10 -> 298050 | M10: 0.74520408 | N10: =+K10*M10 -> 22210.808 | O10: 37.25 | P10: =+K10*O10 -> 1110236.2
B11: 7 | C11: 1010 | D11: 5001211 | E11: DULOXETINE DR CAP 20MG,USA,60 | F11: FG-ANDA | G11: Z_CAPSULE | H11: PA04442 | I11: 60 | J11: BT | K11: 119755 | L11: =K11*I11 -> 7185300 | M11: 4.5222449 | N11: =+K11*M11 -> 541561.44 | O11: 67.05 | P11: =+K11*O11 -> 8029572.8
B12: 8 | C12: 1010 | D12: 5500841 | E12: OMEFOR CAP 20MG,20'S | F12: FG-Domestic | G12: Z_CAPSULE | H12: PA05922 | I12: 20 | J12: STP | K12: 97786 | L12: =K12*I12 -> 1955720 | M12: 1.97 | N12: =+K12*M12 -> 192638.42 | O12: 10.000041 | P12: =+K12*O12 -> 977863.98
B13: 9 | C13: 1010 | D13: 5002247 | E13: DROXIDOPA CAP 100MG,USA,90 | F13: FG-ANDA | G13: Z_CAPSULE | H13: PA04382 | I13: 90 | J13: BT | K13: 1045 | L13: =K13*I13 -> 94050 | M13: 7.1208235 | N13: =+K13*M13 -> 7441.2606 | O13: 1175.6363 | P13: =+K13*O13 -> 1228539.9
B14: 10 | C14: 1010 | D14: 5001240 | E14: ZOLANAS CAP 30MG,IRQ,14 | F14: FG-ROW | G14: Z_CAPSULE | H14: PA03002 | I14: 14 | J14: BT | K14: 28053 | L14: =K14*I14 -> 392742 | M14: 0.094285714 | N14: =+K14*M14 -> 2644.9971 | O14: 29.853446 | P14: =+K14*O14 -> 837478.72
B15: 11 | C15: 1010 | D15: 5002249 | E15: DROXIDOPA CAP 300MG,USA,90 | F15: FG-ANDA | G15: Z_CAPSULE | H15: PA04402 | I15: 90 | J15: BT | K15: 348 | L15: =K15*I15 -> 31320 | M15: 7.1208235 | N15: =+K15*M15 -> 2478.0466 | O15: 3880.9977 | P15: =+K15*O15 -> 1350587.2
B16: 12 | C16: 1010 | D16: 5002249 | E16: DROXIDOPA CAP 300MG,USA,90 | F16: FG-ANDA | G16: Z_CAPSULE | H16: PA04412 | I16: 90 | J16: BT | K16: 357 | L16: =K16*I16 -> 32130 | M16: 7.1208235 | N16: =+K16*M16 -> 2542.134 | O16: 3880.9977 | P16: =+K16*O16 -> 1385516.2
... B19: 15 | C19: 1010 | D19: 5001278 | E19: COXID CAP 400MG,PHL,3X10 | F19: FG-ROW | G19: Z_CAPSULE | H19: PA01432 | I19: 10 | J19: Bl | K19: 18894 | L19: =K19*I19 -> 188940 | M19: 0.7 | N19: =+K19*M19 -> 13225.8 | O19: 94.366667 | P19: =+K19*O19 -> 1782963.8
K20: =SUM(K5:K19) -> 850806 | L20: =SUM(L5:L19) -> 32361098 | N20: =SUM(N5:N19) -> 2491569.6 | P20: =SUM(P5:P19) -> 55324909
B21: 16 | C21: 1010 | D21: 5000670 | E21: DAZEL KIT,NGA/G.EXP,4 | F21: FG-ROW | G21: Z_KIT | H21: PA01612 | I21: 4 | J21: Bl | K21: 631 | L21: =K21*I21 -> 2524 | M21: 0.26 | N21: =+K21*M21 -> 164.06 | O21: 74.5 | P21: =+K21*O21 -> 47009.5
K22: =SUM(K21) -> 631 | L22: =SUM(L21) -> 2524 | N22: =SUM(N21) -> 164.06 | P22: =SUM(P21) -> 47009.5
B23: 17 | C23: 1010 | D23: 5000095 | E23: ROSUCOL TAB 10MG,PHL,3X10 | F23: FG-ROW | G23: Z_TABLET | H23: PA05202 | I23: 10 | J23: STP | K23: 96546 | L23: =K23*I23 -> 965460 | M23: 0.6 | N23: =+K23*M23 -> 57927.6 | O23: 82.5457 | P23: =+K23*O23 -> 7969457.2
B24: 18 | C24: 1010 | D24: 5000810 | E24: WARIK TAB 2.5MG, PHL,3X10 | F24: FG-ROW | G24: Z_TABLET | H24: PA03652 | I24: 10 | J24: Bl | K24: 19149 | L24: =K24*I24 -> 191490 | M24: 0.32 | N24: =+K24*M24 -> 6127.68 | O24: 100.07833 | P24: =+K24*O24 -> 1916400
B25: 19 | C25: 1010 | D25: 5000943 | E25: AMLIFE TAB 50/5MG,PHL(UNITED),3X10 | F25: FG-ROW | G25: Z_TABLET | H25: PA04142 | I25: 10 | J25: Bl | K25: 136728 | L25: =K25*I25 -> 1367280 | M25: 0.34 | N25: =+K25*M25 -> 46487.52 | O25: 71.425631 | P25: =+K25*O25 -> 9765883.7
B26: 20 | C26: 1010 | D26: 5001143 | E26: ROSWIN TAB 5MG,PHL(UNITED),3X10 | F26: FG-ROW | G26: Z_TABLET | H26: PA05212 | I26: 10 | J26: STP | K26: 77595 | L26: =K26*I26 -> 775950 | M26: 0.3 | N26: =+K26*M26 -> 23278.5 | O26: 57.707844 | P26: =+K26*O26 -> 4477840.2
B27: 21 | C27: 1010 | D27: 5001198 | E27: ARIPIPRAZOLE TAB USP 5MG,USA,30 | F27: FG-ANDA | G27: Z_TABLET | H27: PA06692 | I27: 30 | J27: BT | K27: 39099 | L27: =K27*I27 -> 1172970 | M27: 1.1495918 | N27: =+K27*M27 -> 44947.891 | O27: 61.336 | P27: =+K27*O27 -> 2398176.3
B28: 22 | C28: 1010 | D28: 5001321 | E28: ARTEFAN TAB 20/120MG,G.EXP,1X24 | F28: FG-ROW | G28: Z_TABLET | H28: PA05842 | I28: 24 | J28: Bl | K28: 294 | L28: =K28*I28 -> 7056 | M28: 0.674 | N28: =+K28*M28 -> 198.156 | O28: 44.3642 | P28: =+K28*O28 -> 13043.075
B29: 23 | C29: 1010 | D29: 5001599 | E29: SILDENAFIL TAB USP 20MG,USA,90 | F29: FG-ANDA | G29: Z_TABLET | H29: PA07362 | I29: 90 | J29: BT | K29: 49284 | L29: =K29*I29 -> 4435560 | M29: 2.5342708 | N29: =+K29*M29 -> 124899 | O29: 121.356 | P29: =+K29*O29 -> 5980909.1
B30: 24 | C30: 1010 | D30: 5005146 | E30: MUBACT CT 5MG,IRQ,3X10'S | F30: FG-ROW | G30: Z_TABLET | H30: PA05972 | I30: 10 | J30: Bl | K30: 11772 | L30: =K30*I30 -> 117720 | M30: 0.28795918 | N30: =+K30*M30 -> 3389.8555 | O30: 65.063333 | P30: =+K30*O30 -> 765925.56
B31: 25 | C31: 1010 | D31: 5006014 | E31: ADERAN TAB 8MG,IRQ,3X10'S | F31: FG-ROW | G31: Z_TABLET | H31: PA02582 | I31: 10 | J31: Bl | K31: 13920 | L31: =K31*I31 -> 139200 | M31: 0.29395833 | N31: =+K31*M31 -> 4091.9 | O31: 58.402574 | P31: =+K31*O31 -> 812963.83
B32: 26 | C32: 1010 | D32: 5000810 | E32: WARIK TAB 2.5MG, PHL,3X10 | F32: FG-ROW | G32: Z_TABLET | H32: PA03642 | I32: 10 | J32: Bl | K32: 19146 | L32: =K32*I32 -> 191460 | M32: 0.32 | N32: =+K32*M32 -> 6126.72 | O32: 100.07833 | P32: =+K32*O32 -> 1916099.8
B33: 27 | C33: 1010 | D33: 5004390 | E33: ARTEFAN TAB 20/120MG,AA/EXP,30X24 | F33: FG-ROW | G33: Z_TABLET | H33: PA05842 | I33: 24 | J33: Bl | K33: 105936 | L33: =K33*I33 -> 2542464 | M33: 0.674 | N33: =+K33*M33 -> 71400.864 | O33: 37.498333 | P33: =+K33*O33 -> 3972423.4
B34: 28 | C34: 1010 | D34: 5001398 | E34: ROSWIN TAB 10MG,PHL,3X10 | F34: FG-ROW | G34: Z_TABLET | H34: PA03322 | I34: 10 | J34: STP | K34: 97263 | L34: =K34*I34 -> 972630 | M34: 0.28 | N34: =+K34*M34 -> 27233.64 | O34: 92.239027 | P34: =+K34*O34 -> 8971444.5
... B123: 117 | C123: 1010 | D123: 5001471 | E123: ROSUCHOL TAB 10MG,IRQ/G.EXP,3X10 | F123: FG-ROW | G123: Z_TABLET | H123: PA02822 | I123: 10 | J123: Bl | K123: 11655 | L123: =K123*I123 -> 116550 | M123: 0.03 | N123: =+K123*M123 -> 349.65 | O123: 55.875 | P123: =+K123*O123 -> 651223.12
K124: =SUM(K23:K123) -> 5645732 | L124: =SUM(L23:L123) -> 85299575 | N124: =SUM(N23:N123) -> 2783238.8 | P124: =SUM(P23:P123) -> 3.5676939e+08
J126: Total | K126: =K124+K22+K20 -> 6497169 | L126: =L124+L22+L20 -> 117663197 | N126: =N124+N22+N20 -> 5274972.4 | P126: =P124+P22+P20 -> 4.1214131e+08

Sheet Sheet3
A1: Z_CAPSULE
A2: Z_KIT
A3: Z_TABLET
A4: Z_DRY_POWDER_SUSPN
A5: Z_CREAM
A6: Z_EYE_DROPS
A7: Z_FACE CLEANSER
A8: Z_JELLY
A9: Z_LOTION
A10: Z_SUSPENSION
A11: Z_SYRUP
A12: Z_INJECTION
... A15: Z_SOAP

Sheet Plant Master
A1: Plant Code | B1: Plant Name
A2: 1010 | B2: Paithan
A3: 1050 | B3: DAHEJ
A4: 1060 | B4: GUWAHATI
A5: 1070 | B5: PITHAMPUR
A6: 1020 | B6: CHITEGAON
A7: 1030 | B7: CHIKALTHANA
A8: 5070 | B8: CML
A9: 5051 | B9: CML
A10: 5014 | B10: CML
A11: 5028 | B11: CML
A12: 5044 | B12: CML
... A30: 5034 | B30: CML

Sheet DHJ
B2: DAHEJ PLANT
B3: PRODUCTION DETAILS FOR THE MONTH OF APR-2022
B4: Sr. No. | C4: Plant | D4: Material code | E4: Material description | F4: Material Group | G4: Material Class | H4: Batch No | I4: Pack size | J4: Unit | K4: Prodn. Qty. in packs | L4: Qty. in Nos. | M4: DPCO Rate | N4: DPCO Value | O4: VOP Rate | P4: VOP
B5: 1 | C5: 1050 | D5: 5000212 | E5: DIVALPROEX SOD DR CAP USP 125MG,USA,500 | F5: FG-ANDA | G5: Z_CAPSULE | H5: DJ04822 | I5: 500 | J5: BT | K5: 2479 | L5: =I5*K5 -> 1239500 | M5: 29.903061 | N5: =+K5*M5 -> 74129.689 | O5: 3032.15 | P5: =+K5*O5 -> 7516699.9
B6: 2 | C6: 1050 | D6: 5000351 | E6: APRAZOLE CAP 20MG,IRQ,2X7 | F6: FG-ROW | G6: Z_CAPSULE | H6: DJ06442 | I6: 7 | J6: STP | K6: 281478 | L6: =I6*K6 -> 1970346 | M6: 0.57686294 | N6: =+K6*M6 -> 162374.23 | O6: 15.092 | P6: =+K6*O6 -> 4248066
B7: 3 | C7: 1050 | D7: 5000351 | E7: APRAZOLE CAP 20MG,IRQ,2X7 | F7: FG-ROW | G7: Z_CAPSULE | H7: DJ06452 | I7: 7 | J7: STP | K7: 281878 | L7: =I7*K7 -> 1973146 | M7: 0.57686294 | N7: =+K7*M7 -> 162604.97 | O7: 15.092 | P7: =+K7*O7 -> 4254102.8
B8: 4 | C8: 1050 | D8: 5001212 | E8: DULOXETINE DR CAP 30MG,USA,30 | F8: FG-ANDA | G8: Z_CAPSULE | H8: DJ03112 | I8: 30 | J8: BT | K8: 160011 | L8: =I8*K8 -> 4800330 | M8: 2.5473196 | N8: =+K8*M8 -> 407599.15 | O8: 60.42 | P8: =+K8*O8 -> 9667864.6
B9: 5 | C9: 1050 | D9: 5000351 | E9: APRAZOLE CAP 20MG,IRQ,2X7 | F9: FG-ROW | G9: Z_CAPSULE | H9: DJ06422 | I9: 7 | J9: STP | K9: 280878 | L9: =I9*K9 -> 1966146 | M9: 0.57686294 | N9: =+K9*M9 -> 162028.11 | O9: 15.092 | P9: =+K9*O9 -> 4239010.8
B10: 6 | C10: 1050 | D10: 5000351 | E10: APRAZOLE CAP 20MG,IRQ,2X7 | F10: FG-ROW | G10: Z_CAPSULE | H10: DJ06432 | I10: 7 | J10: STP | K10: 283278 | L10: =I10*K10 -> 1982946 | M10: 0.57686294 | N10: =+K10*M10 -> 163412.58 | O10: 15.092 | P10: =+K10*O10 -> 4275231.6
B11: 7 | C11: 1050 | D11: 5001514 | E11: DIVALPROEX SOD DR CAP USP 125MG,USA,1000 | F11: FG-ANDA | G11: Z_CAPSULE | H11: DJ04802 | I11: 1000 | J11: BT | K11: 1243 | L11: =I11*K11 -> 1243000 | M11: 58.071429 | N11: =+K11*M11 -> 72182.786 | O11: 4994.561 | P11: =+K11*O11 -> 6208239.3
B12: 8 | C12: 1050 | D12: 5001620 | E12: OME & SOD BICAR CAP 40/1100MG,USA,30 | F12: FG-ANDA | G12: Z_CAPSULE | H12: DJ03512 | I12: 30 | J12: BT | K12: 4005 | L12: =I12*K12 -> 120150 | M12: 2.5213265 | N12: =+K12*M12 -> 10097.913 | O12: 461.9 | P12: =+K12*O12 -> 1849909.5
B13: 9 | C13: 1050 | D13: 5000500 | E13: TOLTERODINE TARTRATE ER CAP 4MG,USA,30 | F13: FG-ANDA | G13: Z_CAPSULE | H13: DJ06142 | I13: 30 | J13: BT | K13: 20355 | L13: =I13*K13 -> 610650 | M13: 2.5213265 | N13: =+K13*M13 -> 51321.602 | O13: 310.97475 | P13: =+K13*O13 -> 6329891
B14: 10 | C14: 1050 | D14: 5001514 | E14: DIVALPROEX SOD DR CAP USP 125MG,USA,1000 | F14: FG-ANDA | G14: Z_CAPSULE | H14: DJ04792 | I14: 1000 | J14: BT | K14: 613 | L14: =I14*K14 -> 613000 | M14: 58.071429 | N14: =+K14*M14 -> 35597.786 | O14: 4994.561 | P14: =+K14*O14 -> 3061665.9
B15: 11 | C15: 1050 | D15: 5001620 | E15: OME & SOD BICAR CAP 40/1100MG,USA,30 | F15: FG-ANDA | G15: Z_CAPSULE | H15: DJ03502 | I15: 30 | J15: BT | K15: 4029 | L15: =I15*K15 -> 120870 | M15: 2.5213265 | N15: =+K15*M15 -> 10158.425 | O15: 461.9 | P15: =+K15*O15 -> 1860995.1
B16: 12 | C16: 1050 | D16: 5001620 | E16: OME & SOD BICAR CAP 40/1100MG,USA,30 | F16: FG-ANDA | G16: Z_CAPSULE | H16: DJ03492 | I16: 30 | J16: BT | K16: 4029 | L16: =I16*K16 -> 120870 | M16: 2.5213265 | N16: =+K16*M16 -> 10158.425 | O16: 461.9 | P16: =+K16*O16 -> 1860995.1
... B43: 39 | C43: 1050 | D43: 5000502 | E43: TOLTERODINE TARTRATE ER CAP 4MG,USA,500 | F43: FG-ANDA | G43: Z_CAPSULE | H43: DJ06012 | I43: 500 | J43: BT | K43: 198 | L43: =I43*K43 -> 99000 | M43: 29.903061 | N43: =+K43*M43 -> 5920.8061 | O43: 4990.7655 | P43: =+K43*O43 -> 988171.56
K44: =SUM(K5:K43) -> 2263247 | L44: =SUM(L5:L43) -> 44277866 | N44: =SUM(N5:N43) -> 3235008.3 | P44: =SUM(P5:P43) -> 1.4915349e+08
B45: 40 | C45: 1050 | D45: 5001652 | E45: CHOLESTYRAMINE PFOS USP 4GM,USA,60SACH | F45: FG-ANDA | G45: Z_DRY_POWDER_SUSPN | H45: DJ07862 | I45: 1 | J45: SAH | K45: 137385 | L45: =I45*K45 -> 137385 | M45: 0.99132777 | N45: =+K45*M45 -> 136193.57 | O45: 19.073817 | P45: =+K45*O45 -> 2620456.3
B46: 41 | C46: 1050 | D46: 5001652 | E46: CHOLESTYRAMINE PFOS USP 4GM,USA,60SACH | F46: FG-ANDA | G46: Z_DRY_POWDER_SUSPN | H46: DJ07852 | I46: 1 | J46: SAH | K46: 136485 | L46: =I46*K46 -> 136485 | M46: 0.99132777 | N46: =+K46*M46 -> 135301.37 | O46: 19.073817 | P46: =+K46*O46 -> 2603289.9
B47: 42 | C47: 1050 | D47: 5001652 | E47: CHOLESTYRAMINE PFOS USP 4GM,USA,60SACH | F47: FG-ANDA | G47: Z_DRY_POWDER_SUSPN | H47: DJ07842 | I47: 1 | J47: SAH | K47: 135945 | L47: =I47*K47 -> 135945 | M47: 0.99132777 | N47: =+K47*M47 -> 134766.05 | O47: 19.073817 | P47: =+K47*O47 -> 2592990
B48: 43 | C48: 1050 | D48: 5006242 | E48: CHOLESTYRAMINE PFOS USP 4GM,USA,378GMX1 | F48: FG-ANDA | G48: Z_DRY_POWDER_SUSPN | H48: DJ07782 | I48: 1 | J48: BT | K48: 48 | L48: =I48*K48 -> 48 | M48: 0 | N48: =+K48*M48 -> 0 | O48: 0 | P48: =+K48*O48 -> 0
B49: 44 | C49: 1050 | D49: 5006242 | E49: CHOLESTYRAMINE PFOS USP 4GM,USA,378GMX1 | F49: FG-ANDA | G49: Z_DRY_POWDER_SUSPN | H49: DJ07792 | I49: 1 | J49: BT | K49: 49 | L49: =I49*K49 -> 49 | M49: 0 | N49: =+K49*M49 -> 0 | O49: 0 | P49: =+K49*O49 -> 0
B50: 45 | C50: 1050 | D50: 5006243 | E50: CHOLESTYRAMINE PFOS USP 4GM,USA,60SACH | F50: FG-ANDA | G50: Z_DRY_POWDER_SUSPN | H50: DJ07792 | I50: 1 | J50: SAH | K50: 37305 | L50: =I50*K50 -> 37305 | M50: 0 | N50: =+K50*M50 -> 0 | O50: 0 | P50: =+K50*O50 -> 0
B51: 46 | C51: 1050 | D51: 5001652 | E51: CHOLESTYRAMINE PFOS USP 4GM,USA,60SACH | F51: FG-ANDA | G51: Z_DRY_POWDER_SUSPN | H51: DJ07832 | I51: 1 | J51: SAH | K51: 137145 | L51: =I51*K51 -> 137145 | M51: 0.99132777 | N51: =+K51*M51 -> 135955.65 | O51: 19.073817 | P51: =+K51*O51 -> 2615878.6
B52: 47 | C52: 1050 | D52: 5006242 | E52: CHOLESTYRAMINE PFOS USP 4GM,USA,378GMX1 | F52: FG-ANDA | G52: Z_DRY_POWDER_SUSPN | H52: DJ07772 | I52: 1 | J52: BT | K52: 48 | L52: =I52*K52 -> 48 | M52: 0 | N52: =+K52*M52 -> 0 | O52: 0 | P52: =+K52*O52 -> 0
B53: 48 | C53: 1050 | D53: 5001618 | E53: CHOLESTYRAMINE PFOS USP 4GM,USA,378GMX1 | F53: FG-ANDA | G53: Z_DRY_POWDER_SUSPN | H53: DJ04712 | I53: 1 | J53: BT | K53: 3127 | L53: =I53*K53 -> 3127 | M53: 7.1825996 | N53: =+K53*M53 -> 22459.989 | O53: 986.0175 | P53: =+K53*O53 -> 3083276.7
B54: 49 | C54: 1050 | D54: 5006243 | E54: CHOLESTYRAMINE PFOS USP 4GM,USA,60SACH | F54: FG-ANDA | G54: Z_DRY_POWDER_SUSPN | H54: DJ07782 | I54: 1 | J54: SAH | K54: 38745 | L54: =I54*K54 -> 38745 | M54: 0 | N54: =+K54*M54 -> 0 | O54: 0 | P54: =+K54*O54 -> 0
B55: 50 | C55: 1050 | D55: 5001618 | E55: CHOLESTYRAMINE PFOS USP 4GM,USA,378GMX1 | F55: FG-ANDA | G55: Z_DRY_POWDER_SUSPN | H55: DJ04702 | I55: 1 | J55: BT | K55: 3111 | L55: =I55*K55 -> 3111 | M55: 7.1825996 | N55: =+K55*M55 -> 22345.067 | O55: 986.0175 | P55: =+K55*O55 -> 3067500.4
B56: 51 | C56: 1050 | D56: 5006243 | E56: CHOLESTYRAMINE PFOS USP 4GM,USA,60SACH | F56: FG-ANDA | G56: Z_DRY_POWDER_SUSPN | H56: DJ07772 | I56: 1 | J56: SAH | K56: 39165 | L56: =I56*K56 -> 39165 | M56: 0 | N56: =+K56*M56 -> 0 | O56: 0 | P56: =+K56*O56 -> 0
... B63: 58 | C63: 1050 | D63: 5001652 | E63: CHOLESTYRAMINE PFOS USP 4GM,USA,60SACH | F63: FG-ANDA | G63: Z_DRY_POWDER_SUSPN | H63: DJ04652 | I63: 1 | J63: SAH | K63: 135525 | L63: =I63*K63 -> 135525 | M63: 0.99132777 | N63: =+K63*M63 -> 134349.7 | O63: 19.073817 | P63: =+K63*O63 -> 2584979
K64: =SUM(K45:K63) -> 1255682 | L64: =SUM(L45:L63) -> 1255682 | N64: =SUM(N45:N63) -> 1183648.6 | P64: =SUM(P45:P63) -> 34467840
B65: 59 | C65: 1050 | D65: 5000200 | E65: ARTEFAN DT 20/120MG,UGA/G.EXP,30X6 | F65: FG-ROW | G65: Z_TABLET | H65: DJ07582 | I65: 6 | J65: Bl | K65: 309555 | L65: =I65*K65 -> 1857330 | M65: 0.2837551 | N65: =+K65*M65 -> 87837.811 | O65: 19.47945 | P65: =+K65*O65 -> 6029961.1
B66: 60 | C66: 1050 | D66: 5001351 | E66: ARTEFAN TAB 20/120MG,G.EXP,30X18 | F66: FG-ROW | G66: Z_TABLET | H66: DJ06582 | I66: 18 | J66: Bl | K66: 190248 | L66: =I66*K66 -> 3424464 | M66: 0.42861224 | N66: =+K66*M66 -> 81542.622 | O66: 32.77785 | P66: =+K66*O66 -> 6235920.4
B67: 61 | C67: 1050 | D67: 5001534 | E67: FENOFIBRATE TAB USP 160MG,USA,90 | F67: FG-ANDA | G67: Z_TABLET | H67: DJ03332 | I67: 90 | J67: BT | K67: 11455 | L67: =I67*K67 -> 1030950 | M67: 3.0630208 | N67: =+K67*M67 -> 35086.904 | O67: 144.11025 | P67: =+K67*O67 -> 1650782.9
B68: 62 | C68: 1050 | D68: 5002960 | E68: CHLORTHALIDONE TAB USP 25MG,USA,100'S | F68: FG-ANDA | G68: Z_TABLET | H68: DJ02972 | I68: 100 | J68: BT | K68: 19167 | L68: =I68*K68 -> 1916700 | M68: 2.2 | N68: =+K68*M68 -> 42167.4 | O68: 104.3 | P68: =+K68*O68 -> 1999118.1
B69: 63 | C69: 1050 | D69: 5002960 | E69: CHLORTHALIDONE TAB USP 25MG,USA,100'S | F69: FG-ANDA | G69: Z_TABLET | H69: DJ02962 | I69: 100 | J69: BT | K69: 19167 | L69: =I69*K69 -> 1916700 | M69: 2.2 | N69: =+K69*M69 -> 42167.4 | O69: 104.3 | P69: =+K69*O69 -> 1999118.1
B70: 64 | C70: 1050 | D70: 5004756 | E70: RANOLAZINE ER TAB 500MG,USA,60'S | F70: FG-ANDA | G70: Z_TABLET | H70: DJ00292 | I70: 60 | J70: BT | K70: 8216 | L70: =I70*K70 -> 492960 | M70: 3.0345833 | N70: =+K70*M70 -> 24932.137 | O70: 319.9875 | P70: =+K70*O70 -> 2629017.3
B71: 65 | C71: 1050 | D71: 5006034 | E71: ZAHA TAB 500MG,IRQ,10X1X6'S | F71: FG-ROW | G71: Z_TABLET | H71: DJ05712 | I71: 6 | J71: Bl | K71: 79050 | L71: =I71*K71 -> 474300 | M71: 0.37546114 | N71: =+K71*M71 -> 29680.203 | O71: 77.939733 | P71: =+K71*O71 -> 6161135.9
B72: 66 | C72: 1050 | D72: 5001534 | E72: FENOFIBRATE TAB USP 160MG,USA,90 | F72: FG-ANDA | G72: Z_TABLET | H72: DJ03322 | I72: 90 | J72: BT | K72: 11275 | L72: =I72*K72 -> 1014750 | M72: 3.0630208 | N72: =+K72*M72 -> 34535.56 | O72: 144.11025 | P72: =+K72*O72 -> 1624843.1
B73: 67 | C73: 1050 | D73: 5001534 | E73: FENOFIBRATE TAB USP 160MG,USA,90 | F73: FG-ANDA | G73: Z_TABLET | H73: DJ03312 | I73: 90 | J73: BT | K73: 11407 | L73: =I73*K73 -> 1026630 | M73: 3.0630208 | N73: =+K73*M73 -> 34939.879 | O73: 144.11025 | P73: =+K73*O73 -> 1643865.6
...

Sheet GHT
B2: GUWAHATI PLANT
B3: PRODUCTION DETAILS FOR THE MONTH OF APR-2022
B4: Sr. No. | C4: Plant | D4: Material code | E4: Material description | F4: Material Group | G4: Material Class | H4: Batch No | I4: Pack size | J4: Unit | K4: Prodn. Qty. in packs | L4: Qty. in Nos. | M4: DPCO Rate | N4: DPCO Value | O4: VOP Rate | P4: VOP
B5: 1 | C5: 1060 | D5: 5500801 | E5: ROSUFIT CV CAP 10/75MG,15'S | F5: FG-Domestic | G5: Z_CAPSULE | H5: GT04972 | I5: 15 | J5: STP | K5: 32075 | L5: =K5*I5 -> 481125 | M5: 1.1030729 | N5: =+K5*M5 -> 35381.064 | O5: 214.71 | P5: =+K5*O5 -> 6886823.1
B6: 2 | C6: 1060 | D6: 5500800 | E6: ROSUFIT CV CAP 5/75MG,15'S | F6: FG-Domestic | G6: Z_CAPSULE | H6: GT03562 | I6: 15 | J6: STP | K6: 30994 | L6: =K6*I6 -> 464910 | M6: 1.1030729 | N6: =+K6*M6 -> 34188.642 | O6: 175.5 | P6: =+K6*O6 -> 5439447.1
B7: 3 | C7: 1060 | D7: 5500674 | E7: ATORFIT CV CAP 10/75MG,15'S | F7: FG-Domestic | G7: Z_CAPSULE | H7: GT04632 | I7: 15 | J7: Bl | K7: 32871 | L7: =K7*I7 -> 493065 | M7: 0.64 | N7: =+K7*M7 -> 21037.44 | O7: 190.92993 | P7: =+K7*O7 -> 6276057.7
B8: 4 | C8: 1060 | D8: 5500801 | E8: ROSUFIT CV CAP 10/75MG,15'S | F8: FG-Domestic | G8: Z_CAPSULE | H8: GT034121 | I8: 15 | J8: STP | K8: 5950 | L8: =K8*I8 -> 89250 | M8: 1.1030729 | N8: =+K8*M8 -> 6563.2839 | O8: 214.71 | P8: =+K8*O8 -> 1277524.5
B9: 5 | C9: 1060 | D9: 5500674 | E9: ATORFIT CV CAP 10/75MG,15'S | F9: FG-Domestic | G9: Z_CAPSULE | H9: GT04622 | I9: 15 | J9: Bl | K9: 32981 | L9: =K9*I9 -> 494715 | M9: 0.64 | N9: =+K9*M9 -> 21107.84 | O9: 190.92993 | P9: =+K9*O9 -> 6297060
B10: 6 | C10: 1060 | D10: 5500674 | E10: ATORFIT CV CAP 10/75MG,15'S | F10: FG-Domestic | G10: Z_CAPSULE | H10: GT04612 | I10: 15 | J10: Bl | K10: 32911 | L10: =K10*I10 -> 493665 | M10: 0.64 | N10: =+K10*M10 -> 21063.04 | O10: 190.92993 | P10: =+K10*O10 -> 6283694.9
B11: 7 | C11: 1060 | D11: 5500674 | E11: ATORFIT CV CAP 10/75MG,15'S | F11: FG-Domestic | G11: Z_CAPSULE | H11: GT04602 | I11: 15 | J11: Bl | K11: 32971 | L11: =K11*I11 -> 494565 | M11: 0.64 | N11: =+K11*M11 -> 21101.44 | O11: 190.92993 | P11: =+K11*O11 -> 6295150.7
B12: 8 | C12: 1060 | D12: 5500675 | E12: ATORFIT CV CAP 20/75MG,15'S | F12: FG-Domestic | G12: Z_CAPSULE | H12: GT04592 | I12: 15 | J12: Bl | K12: 32951 | L12: =K12*I12 -> 494265 | M12: 0.64 | N12: =+K12*M12 -> 21088.64 | O12: 235.29 | P12: =+K12*O12 -> 7753040.7
B13: 9 | C13: 1060 | D13: 5500801 | E13: ROSUFIT CV CAP 10/75MG,15'S | F13: FG-Domestic | G13: Z_CAPSULE | H13: GT03412 | I13: 15 | J13: STP | K13: 26590 | L13: =K13*I13 -> 398850 | M13: 1.1030729 | N13: =+K13*M13 -> 29330.709 | O13: 214.71 | P13: =+K13*O13 -> 5709138.8
B14: 10 | C14: 1060 | D14: 5500675 | E14: ATORFIT CV CAP 20/75MG,15'S | F14: FG-Domestic | G14: Z_CAPSULE | H14: GT03732 | I14: 15 | J14: Bl | K14: 33101 | L14: =K14*I14 -> 496515 | M14: 0.64 | N14: =+K14*M14 -> 21184.64 | O14: 235.29 | P14: =+K14*O14 -> 7788334.2
K15: =SUM(K5:K14) -> 293395 | L15: =SUM(L5:L14) -> 4400925 | N15: =SUM(N5:N14) -> 232046.74 | P15: =SUM(P5:P14) -> 60006271
B16: 11 | C16: 1060 | D16: 5005000 | E16: MOMADERM OINTMENT 0.1%W/W,IRQ,30GM | F16: FG-ROW | G16: Z_CREAM | H16: G1757 | I16: 1 | J16: Tb | K16: 9578 | L16: =K16*I16 -> 9578 | M16: 1.2737412 | N16: =+K16*M16 -> 12199.893 | O16: 131.12 | P16: =+K16*O16 -> 1255867.4
B17: 12 | C17: 1060 | D17: 5501153 | E17: MELACARE CREAM 2/0.025/0.1%W/W,25GM | F17: FG-Domestic | G17: Z_CREAM | H17: G1764 | I17: 1 | J17: Tb | K17: 79281 | L17: =K17*I17 -> 79281 | M17: 1.1602041 | N17: =+K17*M17 -> 91982.14 | O17: 166.50015 | P17: =+K17*O17 -> 13200298
B18: 13 | C18: 1060 | D18: 5501153 | E18: MELACARE CREAM 2/0.025/0.1%W/W,25GM | F18: FG-Domestic | G18: Z_CREAM | H18: G1763 | I18: 1 | J18: Tb | K18: 79399 | L18: =K18*I18 -> 79399 | M18: 1.1602041 | N18: =+K18*M18 -> 92119.044 | O18: 166.50015 | P18: =+K18*O18 -> 13219945
B19: 14 | C19: 1060 | D19: 5501340 | E19: LUCOZ XL CREAM 1%W/W,50GM | F19: FG-Domestic | G19: Z_CREAM | H19: G1760 | I19: 1 | J19: Tb | K19: 11849 | L19: =K19*I19 -> 11849 | M19: 2.0959184 | N19: =+K19*M19 -> 24834.537 | O19: 183.21172 | P19: =+K19*O19 -> 2170875.7
B20: 15 | C20: 1060 | D20: 5000507 | E20: MOMADERM CREAM 0.1%,G.EXP,30GM | F20: FG-ROW | G20: Z_CREAM | H20: G1755 | I20: 1 | J20: Tb | K20: 9899 | L20: =K20*I20 -> 9899 | M20: 1.2868725 | N20: =+K20*M20 -> 12738.751 | O20: 113.2875 | P20: =+K20*O20 -> 1121433
B21: 16 | C21: 1060 | D21: 5500930 | E21: AQUASOFT MAX CREAM,100GM | F21: FG-Domestic | G21: Z_CREAM | H21: G17191 | I21: 1 | J21: Tb | K21: 489 | L21: =K21*I21 -> 489 | M21: 3.5591837 | N21: =+K21*M21 -> 1740.4408 | O21: 232.47 | P21: =+K21*O21 -> 113677.83
B22: 17 | C22: 1060 | D22: 5501153 | E22: MELACARE CREAM 2/0.025/0.1%W/W,25GM | F22: FG-Domestic | G22: Z_CREAM | H22: G1728 | I22: 1 | J22: Tb | K22: 79254 | L22: =K22*I22 -> 79254 | M22: 1.1602041 | N22: =+K22*M22 -> 91950.814 | O22: 166.50015 | P22: =+K22*O22 -> 13195803
B23: 18 | C23: 1060 | D23: 5000337 | E23: MELACARE CREAM,E/F/V/G.EXP,15GM | F23: FG-ROW | G23: Z_CREAM | H23: G1753 | I23: 1 | J23: Tb | K23: 65828 | L23: =K23*I23 -> 65828 | M23: 0.93284009 | N23: =+K23*M23 -> 61406.998 | O23: 118.3221 | P23: =+K23*O23 -> 7788907.2
B24: 19 | C24: 1060 | D24: 5000507 | E24: MOMADERM CREAM 0.1%,G.EXP,30GM | F24: FG-ROW | G24: Z_CREAM | H24: G1754 | I24: 1 | J24: Tb | K24: 9809 | L24: =K24*I24 -> 9809 | M24: 1.2868725 | N24: =+K24*M24 -> 12622.933 | O24: 113.2875 | P24: =+K24*O24 -> 1111237.1
B25: 20 | C25: 1060 | D25: 5500943 | E25: AQUASOFT MAX CREAM,150GM | F25: FG-Domestic | G25: Z_CREAM | H25: G1719 | I25: 1 | J25: Tb | K25: 2982 | L25: =K25*I25 -> 2982 | M25: 4.6942141 | N25: =+K25*M25 -> 13998.146 | O25: 284.95 | P25: =+K25*O25 -> 849720.9
B26: 21 | C26: 1060 | D26: 5000337 | E26: MELACARE CREAM,E/F/V/G.EXP,15GM | F26: FG-ROW | G26: Z_CREAM | H26: G1752 | I26: 1 | J26: Tb | K26: 65361 | L26: =K26*I26 -> 65361 | M26: 0.93284009 | N26: =+K26*M26 -> 60971.361 | O26: 118.3221 | P26: =+K26*O26 -> 7733650.8
B27: 22 | C27: 1060 | D27: 5500024 | E27: PEROCLIN GEL 2.5%,15GM | F27: FG-Domestic | G27: Z_CREAM | H27: G1746 | I27: 1 | J27: Tb | K27: 19228 | L27: =K27*I27 -> 19228 | M27: 0.93284009 | N27: =+K27*M27 -> 17936.649 | O27: 283.49 | P27: =+K27*O27 -> 5450945.7
... B48: 43 | C48: 1060 | D48: 5500943 | E48: AQUASOFT MAX CREAM,150GM | F48: FG-Domestic | G48: Z_CREAM | H48: G1717 | I48: 1 | J48: Tb | K48: 3311 | L48: =K48*I48 -> 3311 | M48: 4.6942141 | N48: =+K48*M48 -> 15542.543 | O48: 284.95 | P48: =+K48*O48 -> 943469.45
K49: =SUM(K16:K48) -> 705273 | L49: =SUM(L16:L48) -> 705273 | N49: =SUM(N16:N48) -> 920043.02 | P49: =SUM(P16:P48) -> 1.133985e+08
B50: 44 | C50: 1060 | D50: 5002064 | E50: ARTEFAN PFOS 40/240MG,FA,30ML | F50: FG-ROW | G50: Z_DRY_POWDER_SUSPN | H50: GT05242 | I50: 1 | J50: BT | K50: 6828 | L50: =K50*I50 -> 6828 | M50: 1.1814286 | N50: =+K50*M50 -> 8066.7943 | O50: 115.33345 | P50: =+K50*O50 -> 787496.8
B51: 45 | C51: 1060 | D51: 5002063 | E51: ARTEFAN PFOS 20/120MG,FA,30ML | F51: FG-ROW | G51: Z_DRY_POWDER_SUSPN | H51: GT05352 | I51: 1 | J51: BT | K51: 6815 | L51: =K51*I51 -> 6815 | M51: 1.1814286 | N51: =+K51*M51 -> 8051.4357 | O51: 76.60835 | P51: =+K51*O51 -> 522085.91
B52: 46 | C52: 1060 | D52: 5002063 | E52: ARTEFAN PFOS 20/120MG,FA,30ML | F52: FG-ROW | G52: Z_DRY_POWDER_SUSPN | H52: GT05342 | I52: 1 | J52: BT | K52: 6861 | L52: =K52*I52 -> 6861 | M52: 1.1814286 | N52: =+K52*M52 -> 8105.7814 | O52: 76.60835 | P52: =+K52*O52 -> 525609.89
B53: 47 | C53: 1060 | D53: 5002063 | E53: ARTEFAN PFOS 20/120MG,FA,30ML | F53: FG-ROW | G53: Z_DRY_POWDER_SUSPN | H53: GT05332 | I53: 1 | J53: BT | K53: 6848 | L53: =K53*I53 -> 6848 | M53: 1.1814286 | N53: =+K53*M53 -> 8090.4229 | O53: 76.60835 | P53: =+K53*O53 -> 524613.98
B54: 48 | C54: 1060 | D54: 5002063 | E54: ARTEFAN PFOS 20/120MG,FA,30ML | F54: FG-ROW | G54: Z_DRY_POWDER_SUSPN | H54: GT05312 | I54: 1 | J54: BT | K54: 6847 | L54: =K54*I54 -> 6847 | M54: 1.1814286 | N54: =+K54*M54 -> 8089.2414 | O54: 76.60835 | P54: =+K54*O54 -> 524537.37
B55: 49 | C55: 1060 | D55: 5002063 | E55: ARTEFAN PFOS 20/120MG,FA,30ML | F55: FG-ROW | G55: Z_DRY_POWDER_SUSPN | H55: GT05322 | I55: 1 | J55: BT | K55: 6846 | L55: =K55*I55 -> 6846 | M55: 1.1814286 | N55: =+K55*M55 -> 8088.06 | O55: 76.60835 | P55: =+K55*O55 -> 524460.76
B56: 50 | C56: 1060 | D56: 5002063 | E56: ARTEFAN PFOS 20/120MG,FA,30ML | F56: FG-ROW | G56: Z_DRY_POWDER_SUSPN | H56: GT05302 | I56: 1 | J56: BT | K56: 6851 | L56: =K56*I56 -> 6851 | M56: 1.1814286 | N56: =+K56*M56 -> 8093.9671 | O56: 76.60835 | P56: =+K56*O56 -> 524843.81
B57: 51 | C57: 1060 | D57: 5002063 | E57: ARTEFAN PFOS 20/120MG,FA,30ML | F57: FG-ROW | G57: Z_DRY_POWDER_SUSPN | H57: GT05292 | I57: 1 | J57: BT | K57: 6837 | L57: =K57*I57 -> 6837 | M57: 1.1814286 | N57: =+K57*M57 -> 8077.4271 | O57: 76.60835 | P57: =+K57*O57 -> 523771.29
B58: 52 | C58: 1060 | D58: 5002063 | E58: ARTEFAN PFOS 20/120MG,FA,30ML | F58: FG-ROW | G58: Z_DRY_POWDER_SUSPN | H58: GT05282 | I58: 1 | J58: BT | K58: 6819 | L58: =K58*I58 -> 6819 | M58: 1.1814286 | N58: =+K58*M58 -> 8056.1614 | O58: 76.60835 | P58: =+K58*O58 -> 522392.34
B59: 53 | C59: 1060 | D59: 5002063 | E59: ARTEFAN PFOS 20/120MG,FA,30ML | F59: FG-ROW | G59: Z_DRY_POWDER_SUSPN | H59: GT03542 | I59: 1 | J59: BT | K59: 6837 | L59: =K59*I59 -> 6837 | M59: 1.1814286 | N59: =+K59*M59 -> 8077.4271 | O59: 76.60835 | P59: =+K59*O59 -> 523771.29
B60: 54 | C60: 1060 | D60: 5002063 | E60: ARTEFAN PFOS 20/120MG,FA,30ML | F60: FG-ROW | G60: Z_DRY_POWDER_SUSPN | H60: GT03532 | I60: 1 | J60: BT | K60: 6840 | L60: =K60*I60 -> 6840 | M60: 1.1814286 | N60: =+K60*M60 -> 8080.9714 | O60: 76.60835 | P60: =+K60*O60 -> 524001.11
B61: 55 | C61: 1060 | D61: 5002063 | E61: ARTEFAN PFOS 20/120MG,FA,30ML | F61: FG-ROW | G61: Z_DRY_POWDER_SUSPN | H61: GT03522 | I61: 1 | J61: BT | K61: 6852 | L61: =K61*I61 -> 6852 | M61: 1.1814286 | N61: =+K61*M61 -> 8095.1486 | O61: 76.60835 | P61: =+K61*O61 -> 524920.41
...

Sheet PMR
B2: PITHAMPUR PLANT
B3: PRODUCTION DETAILS FOR THE MONTH OF APR-2022
B4: Sr. No. | C4: Plant | D4: Material code | E4: Material description | F4: Material Group | G4: Material Class | H4: Batch No | I4: Pack size | J4: Unit | K4: Prodn. Qty. in packs | L4: Qty. in Nos. | M4: DPCO Rate | N4: DPCO Value | O4: VOP Rate | P4: VOP
B5: 1 | C5: 1070 | D5: 5001041 | E5: FEDATE CAP,FA,3X10 | F5: FG-ROW | G5: Z_CAPSULE | H5: PM01792 | I5: 10 | J5: Bl | K5: 44754 | L5: =K5*I5 -> 447540 | M5: 0.74520408 | N5: =+K5*M5 -> 33350.863 | O5: 47.1436 | P5: =+K5*O5 -> 2109864.7
B6: 2 | C6: 1070 | D6: 5001041 | E6: FEDATE CAP,FA,3X10 | F6: FG-ROW | G6: Z_CAPSULE | H6: PM01782 | I6: 10 | J6: Bl | K6: 44190 | L6: =K6*I6 -> 441900 | M6: 0.74520408 | N6: =+K6*M6 -> 32930.568 | O6: 47.1436 | P6: =+K6*O6 -> 2083275.7
B7: 3 | C7: 1070 | D7: 5001041 | E7: FEDATE CAP,FA,3X10 | F7: FG-ROW | G7: Z_CAPSULE | H7: PM01772 | I7: 10 | J7: Bl | K7: 44052 | L7: =K7*I7 -> 440520 | M7: 0.74520408 | N7: =+K7*M7 -> 32827.73 | O7: 47.1436 | P7: =+K7*O7 -> 2076769.9
B8: 4 | C8: 1070 | D8: 5001508 | E8: ULCIZONE CAP 20MG,FA,1X14 | F8: FG-ROW | G8: Z_CAPSULE | H8: PM01282 | I8: 14 | J8: Bl | K8: 21111 | L8: =K8*I8 -> 295554 | M8: 1.0134898 | N8: =+K8*M8 -> 21395.783 | O8: 165.84445 | P8: =+K8*O8 -> 3501142.2
K9: =SUM(K5:K8) -> 154107 | L9: =SUM(L5:L8) -> 1625514 | N9: =SUM(N5:N8) -> 120504.95 | P9: =SUM(P5:P8) -> 9771052.4
B10: 5 | C10: 1070 | D10: 5005910 | E10: ACTINAC TAB 100MG,IRQ,2X10'S | F10: FG-ROW | G10: Z_TABLET | H10: PM01552 | I10: 10 | J10: Bl | K10: 47480 | L10: =K10*I10 -> 474800 | M10: 0.34 | N10: =+K10*M10 -> 16143.2 | O10: 35.3875 | P10: =+K10*O10 -> 1680198.5
B11: 6 | C11: 1070 | D11: 5001391 | E11: ATORFIT TAB 20MG,FA,3X10 | F11: FG-ROW | G11: Z_TABLET | H11: PM01272 | I11: 10 | J11: Bl | K11: 42318 | L11: =K11*I11 -> 423180 | M11: 0.34177083 | N11: =+K11*M11 -> 14463.058 | O11: 90.724562 | P11: =+K11*O11 -> 3839282
B12: 7 | C12: 1070 | D12: 5004853 | E12: ACTINAC PLUS TAB 100/500MG,IRQ,2X10'S PV | F12: FG-ROW | G12: Z_TABLET | H12: PM01712 | I12: 10 | J12: Bl | K12: 51898 | L12: =K12*I12 -> 518980 | M12: 0.49708333 | N12: =+K12*M12 -> 25797.631 | O12: 43.344584 | P12: =+K12*O12 -> 2249497.2
B13: 8 | C13: 1070 | D13: 5001391 | E13: ATORFIT TAB 20MG,FA,3X10 | F13: FG-ROW | G13: Z_TABLET | H13: PM01262 | I13: 10 | J13: Bl | K13: 43236 | L13: =K13*I13 -> 432360 | M13: 0.34177083 | N13: =+K13*M13 -> 14776.804 | O13: 90.724562 | P13: =+K13*O13 -> 3922567.2
B14: 9 | C14: 1070 | D14: 5004853 | E14: ACTINAC PLUS TAB 100/500MG,IRQ,2X10'S PV | F14: FG-ROW | G14: Z_TABLET | H14: PM01692 | I14: 10 | J14: Bl | K14: 51984 | L14: =K14*I14 -> 519840 | M14: 0.49708333 | N14: =+K14*M14 -> 25840.38 | O14: 43.344584 | P14: =+K14*O14 -> 2253224.9
B15: 10 | C15: 1070 | D15: 5001391 | E15: ATORFIT TAB 20MG,FA,3X10 | F15: FG-ROW | G15: Z_TABLET | H15: PM01252 | I15: 10 | J15: Bl | K15: 42774 | L15: =K15*I15 -> 427740 | M15: 0.34177083 | N15: =+K15*M15 -> 14618.906 | O15: 90.724562 | P15: =+K15*O15 -> 3880652.4
B16: 11 | C16: 1070 | D16: 5004853 | E16: ACTINAC PLUS TAB 100/500MG,IRQ,2X10'S PV | F16: FG-ROW | G16: Z_TABLET | H16: PM01432 | I16: 10 | J16: Bl | K16: 51662 | L16: =K16*I16 -> 516620 | M16: 0.49708333 | N16: =+K16*M16 -> 25680.319 | O16: 43.344584 | P16: =+K16*O16 -> 2239267.9
B17: 12 | C17: 1070 | D17: 5004872 | E17: RUPTEX TAB 10MG,FA,2X10'S | F17: FG-ROW | G17: Z_TABLET | H17: PM01512 | I17: 10 | J17: Bl | K17: 7782 | L17: =K17*I17 -> 77820 | M17: 0.29395833 | N17: =+K17*M17 -> 2287.5837 | O17: 0 | P17: =+K17*O17 -> 0
B18: 13 | C18: 1070 | D18: 5004853 | E18: ACTINAC PLUS TAB 100/500MG,IRQ,2X10'S PV | F18: FG-ROW | G18: Z_TABLET | H18: PM01422 | I18: 10 | J18: Bl | K18: 52066 | L18: =K18*I18 -> 520660 | M18: 0.49708333 | N18: =+K18*M18 -> 25881.141 | O18: 43.344584 | P18: =+K18*O18 -> 2256779.1
B19: 14 | C19: 1070 | D19: 5001764 | E19: ARTEFAN TAB 80/480MG,FA,1X6 | F19: FG-ROW | G19: Z_TABLET | H19: PM01362 | I19: 6 | J19: Bl | K19: 57448 | L19: =K19*I19 -> 344688 | M19: 0.33132653 | N19: =+K19*M19 -> 19034.047 | O19: 78.07354 | P19: =+K19*O19 -> 4485168.7
B20: 15 | C20: 1070 | D20: 5001153 | E20: DYLDES TAB 5MG,FA,15 | F20: FG-ROW | G20: Z_TABLET | H20: PM00702 | I20: 15 | J20: Bl | K20: 15580 | L20: =K20*I20 -> 233700 | M20: 0.47463542 | N20: =+K20*M20 -> 7394.8198 | O20: 204.53104 | P20: =+K20*O20 -> 3186593.6
B21: 16 | C21: 1070 | D21: 5004853 | E21: ACTINAC PLUS TAB 100/500MG,IRQ,2X10'S PV | F21: FG-ROW | G21: Z_TABLET | H21: PM01412 | I21: 10 | J21: Bl | K21: 52006 | L21: =K21*I21 -> 520060 | M21: 0.49708333 | N21: =+K21*M21 -> 25851.316 | O21: 43.344584 | P21: =+K21*O21 -> 2254178.5
... B48: 43 | C48: 1070 | D48: 5004853 | E48: ACTINAC PLUS TAB 100/500MG,IRQ,2X10'S PV | F48: FG-ROW | G48: Z_TABLET | H48: PM00962 | I48: 10 | J48: Bl | K48: 51572 | L48: =K48*I48 -> 515720 | M48: 0.49708333 | N48: =+K48*M48 -> 25635.582 | O48: 43.344584 | P48: =+K48*O48 -> 2235366.9
K49: =SUM(K10:K48) -> 1939252 | L49: =SUM(L10:L48) -> 15764129 | N49: =SUM(N10:N48) -> 730844.95 | P49: =SUM(P10:P48) -> 1.4084896e+08
J51: Total | K51: =K49+K9 -> 2093359 | L51: =L49+L9 -> 17389643 | N51: =N49+N9 -> 851349.9 | P51: =P49+P9 -> 1.5062002e+08

Sheet CTGN
B2: CHITEGAON PLANT
B3: PRODUCTION DETAILS FOR THE MONTH OF APR-2022
B4: Sr. No. | C4: Plant | D4: Material code | E4: Material description | F4: Material Group | G4: Material Class | H4: Batch No | I4: Pack size | J4: Unit | K4: Prodn. Qty. in packs | L4: Qty. in Nos. | M4: DPCO Rate | N4: DPCO Value | O4: VOP Rate | P4: VOP
B5: 1 | C5: 1020 | D5: 5001461 | E5: APLENE CAP 75MG,G.EXP,1X14 | F5: FG-ROW | G5: Z_CAPSULE | H5: CT02722 | I5: 14 | J5: Bl | K5: 34365 | L5: =K5*I5 -> 481110 | M5: 1.0134898 | N5: =+K5*M5 -> 34828.577 | O5: 102.735 | P5: =+K5*O5 -> 3530488.3
K6: =SUM(K5) -> 34365 | L6: =SUM(L5) -> 481110 | N6: =SUM(N5) -> 34828.577 | P6: =SUM(P5) -> 3530488.3
B7: 2 | C7: 1020 | D7: 5004370 | E7: APFLU PFOS 500/25/200MG,FA,10X13.0GM | F7: FG-ROW | G7: Z_DRY_POWDER_SUSPN | H7: CT03692 | I7: 1 | J7: SAH | K7: 19600 | L7: =K7*I7 -> 19600 | M7: 1.0682127 | N7: =+K7*M7 -> 20936.969 | O7: 13.6354 | P7: =+K7*O7 -> 267253.84
B8: 3 | C8: 1020 | D8: 5004370 | E8: APFLU PFOS 500/25/200MG,FA,10X13.0GM | F8: FG-ROW | G8: Z_DRY_POWDER_SUSPN | H8: CT03682 | I8: 1 | J8: SAH | K8: 19500 | L8: =K8*I8 -> 19500 | M8: 1.0682127 | N8: =+K8*M8 -> 20830.148 | O8: 13.6354 | P8: =+K8*O8 -> 265890.3
B9: 4 | C9: 1020 | D9: 5004370 | E9: APFLU PFOS 500/25/200MG,FA,10X13.0GM | F9: FG-ROW | G9: Z_DRY_POWDER_SUSPN | H9: CT03672 | I9: 1 | J9: SAH | K9: 19600 | L9: =K9*I9 -> 19600 | M9: 1.0682127 | N9: =+K9*M9 -> 20936.969 | O9: 13.6354 | P9: =+K9*O9 -> 267253.84
B10: 5 | C10: 1020 | D10: 5004370 | E10: APFLU PFOS 500/25/200MG,FA,10X13.0GM | F10: FG-ROW | G10: Z_DRY_POWDER_SUSPN | H10: CT03042 | I10: 1 | J10: SAH | K10: 19650 | L10: =K10*I10 -> 19650 | M10: 1.0682127 | N10: =+K10*M10 -> 20990.38 | O10: 13.6354 | P10: =+K10*O10 -> 267935.61
B11: 6 | C11: 1020 | D11: 5004370 | E11: APFLU PFOS 500/25/200MG,FA,10X13.0GM | F11: FG-ROW | G11: Z_DRY_POWDER_SUSPN | H11: CT03032 | I11: 1 | J11: SAH | K11: 19350 | L11: =K11*I11 -> 19350 | M11: 1.0682127 | N11: =+K11*M11 -> 20669.916 | O11: 13.6354 | P11: =+K11*O11 -> 263844.99
B12: 7 | C12: 1020 | D12: 5004370 | E12: APFLU PFOS 500/25/200MG,FA,10X13.0GM | F12: FG-ROW | G12: Z_DRY_POWDER_SUSPN | H12: CT03012 | I12: 1 | J12: SAH | K12: 19600 | L12: =K12*I12 -> 19600 | M12: 1.0682127 | N12: =+K12*M12 -> 20936.969 | O12: 13.6354 | P12: =+K12*O12 -> 267253.84
B13: 8 | C13: 1020 | D13: 5004370 | E13: APFLU PFOS 500/25/200MG,FA,10X13.0GM | F13: FG-ROW | G13: Z_DRY_POWDER_SUSPN | H13: CT03022 | I13: 1 | J13: SAH | K13: 19550 | L13: =K13*I13 -> 19550 | M13: 1.0682127 | N13: =+K13*M13 -> 20883.559 | O13: 13.6354 | P13: =+K13*O13 -> 266572.07
B14: 9 | C14: 1020 | D14: 5004370 | E14: APFLU PFOS 500/25/200MG,FA,10X13.0GM | F14: FG-ROW | G14: Z_DRY_POWDER_SUSPN | H14: CT02732 | I14: 1 | J14: SAH | K14: 19300 | L14: =K14*I14 -> 19300 | M14: 1.0682127 | N14: =+K14*M14 -> 20616.505 | O14: 13.6354 | P14: =+K14*O14 -> 263163.22
B15: 10 | C15: 1020 | D15: 5004370 | E15: APFLU PFOS 500/25/200MG,FA,10X13.0GM | F15: FG-ROW | G15: Z_DRY_POWDER_SUSPN | H15: CT01722 | I15: 1 | J15: SAH | K15: 19600 | L15: =K15*I15 -> 19600 | M15: 1.0682127 | N15: =+K15*M15 -> 20936.969 | O15: 13.6354 | P15: =+K15*O15 -> 267253.84
B16: 11 | C16: 1020 | D16: 5004370 | E16: APFLU PFOS 500/25/200MG,FA,10X13.0GM | F16: FG-ROW | G16: Z_DRY_POWDER_SUSPN | H16: CT01712 | I16: 1 | J16: SAH | K16: 19700 | L16: =K16*I16 -> 19700 | M16: 1.0682127 | N16: =+K16*M16 -> 21043.79 | O16: 13.6354 | P16: =+K16*O16 -> 268617.38
K17: =SUM(K7:K16) -> 195450 | L17: =SUM(L7:L16) -> 195450 | N17: =SUM(N7:N16) -> 208782.18 | P17: =SUM(P7:P16) -> 2665038.9
B18: 12 | C18: 1020 | D18: 5000866 | E18: KAMAGRA JELY 50,G.EXP,7,M/P/O/S/MA/B/BL | F18: FG-ROW | G18: Z_JELLY | H18: CT03352 | I18: 1 | J18: SAH | K18: 259245 | L18: =K18*I18 -> 259245 | M18: 0.63394613 | N18: =+K18*M18 -> 164347.37 | O18: 16.602857 | P18: =+K18*O18 -> 4304207.7
B19: 13 | C19: 1020 | D19: 5002910 | E19: KAMAGRA JELY 100MG/5GM,SING,1SAC,BLC,ES | F19: FG-ROW | G19: Z_JELLY | H19: CT03782 | I19: 1 | J19: SAH | K19: 98460 | L19: =K19*I19 -> 98460 | M19: 0.6205999 | N19: =+K19*M19 -> 61104.266 | O19: 11.92 | P19: =+K19*O19 -> 1173643.2
B20: 14 | C20: 1020 | D20: 5002913 | E20: KAMAGRA JELY 100MG/5GM,SING,1SAC,BNA,ES | F20: FG-ROW | G20: Z_JELLY | H20: CT03802 | I20: 1 | J20: SAH | K20: 98860 | L20: =K20*I20 -> 98860 | M20: 0.6205999 | N20: =+K20*M20 -> 61352.506 | O20: 11.92 | P20: =+K20*O20 -> 1178411.2
B21: 15 | C21: 1020 | D21: 5002913 | E21: KAMAGRA JELY 100MG/5GM,SING,1SAC,BNA,ES | F21: FG-ROW | G21: Z_JELLY | H21: CT03792 | I21: 1 | J21: SAH | K21: 98860 | L21: =K21*I21 -> 98860 | M21: 0.6205999 | N21: =+K21*M21 -> 61352.506 | O21: 11.92 | P21: =+K21*O21 -> 1178411.2
B22: 16 | C22: 1020 | D22: 5002910 | E22: KAMAGRA JELY 100MG/5GM,SING,1SAC,BLC,ES | F22: FG-ROW | G22: Z_JELLY | H22: CT03772 | I22: 1 | J22: SAH | K22: 98810 | L22: =K22*I22 -> 98810 | M22: 0.6205999 | N22: =+K22*M22 -> 61321.476 | O22: 11.92 | P22: =+K22*O22 -> 1177815.2
B23: 17 | C23: 1020 | D23: 5001944 | E23: KAMAGRA JELLY 100MG/5GM,G.EXP,7,VOL I ES | F23: FG-ROW | G23: Z_JELLY | H23: CT02242 | I23: 1 | J23: SAH | K23: 112560 | L23: =K23*I23 -> 112560 | M23: 0.6205999 | N23: =+K23*M23 -> 69854.724 | O23: 12.771429 | P23: =+K23*O23 -> 1437552
B24: 18 | C24: 1020 | D24: 5002914 | E24: KAMAGRA JELY 100MG/5GM,SING,1SAC,STW,ES | F24: FG-ROW | G24: Z_JELLY | H24: CT02752 | I24: 1 | J24: SAH | K24: 99160 | L24: =K24*I24 -> 99160 | M24: 0.6205999 | N24: =+K24*M24 -> 61538.686 | O24: 11.92 | P24: =+K24*O24 -> 1181987.2
B25: 19 | C25: 1020 | D25: 5002914 | E25: KAMAGRA JELY 100MG/5GM,SING,1SAC,STW,ES | F25: FG-ROW | G25: Z_JELLY | H25: CT02742 | I25: 1 | J25: SAH | K25: 98060 | L25: =K25*I25 -> 98060 | M25: 0.6205999 | N25: =+K25*M25 -> 60856.026 | O25: 11.92 | P25: =+K25*O25 -> 1168875.2
B26: 20 | C26: 1020 | D26: 5002914 | E26: KAMAGRA JELY 100MG/5GM,SING,1SAC,STW,ES | F26: FG-ROW | G26: Z_JELLY | H26: CT02762 | I26: 1 | J26: SAH | K26: 98710 | L26: =K26*I26 -> 98710 | M26: 0.6205999 | N26: =+K26*M26 -> 61259.416 | O26: 11.92 | P26: =+K26*O26 -> 1176623.2
K27: =SUM(K18:K26) -> 1062725 | L27: =SUM(L18:L26) -> 1062725 | N27: =SUM(N18:N26) -> 662986.97 | P27: =SUM(P18:P26) -> 13977526
B28: 21 | C28: 1020 | D28: 5000335 | E28: METROSULE TAB 500MG,IRQ,10X10 | F28: FG-ROW | G28: Z_TABLET | H28: CT03652 | I28: 10 | J28: Bl | K28: 89669 | L28: =K28*I28 -> 896690 | M28: 0.42295918 | N28: =+K28*M28 -> 37926.327 | O28: 9.4809374 | P28: =+K28*O28 -> 850146.17
B29: 22 | C29: 1020 | D29: 5500520 | E29: METXL 3D TAB 25/12.5/40MG,15'S | F29: FG-Domestic | G29: Z_TABLET | H29: CT03572 | I29: 15 | J29: Bl | K29: 19721 | L29: =K29*I29 -> 295815 | M29: 0.47463542 | N29: =+K29*M29 -> 9360.2851 | O29: 136.93 | P29: =+K29*O29 -> 2700396.6
B30: 23 | C30: 1020 | D30: 5000335 | E30: METROSULE TAB 500MG,IRQ,10X10 | F30: FG-ROW | G30: Z_TABLET | H30: CT03642 | I30: 10 | J30: Bl | K30: 89669 | L30: =K30*I30 -> 896690 | M30: 0.42295918 | N30: =+K30*M30 -> 37926.327 | O30: 9.4809374 | P30: =+K30*O30 -> 850146.17
B31: 24 | C31: 1020 | D31: 5002007 | E31: APRAMOL EFT 1000MG,G.EXP,1X8 | F31: FG-ROW | G31: Z_TABLET | H31: CT03822 | I31: 8 | J31: Tb | K31: 9887 | L31: =K31*I31 -> 79096 | M31: 0.45118367 | N31: =+K31*M31 -> 4460.853 | O31: 68.177014 | P31: =+K31*O31 -> 674066.13
B32: 25 | C32: 1020 | D32: 5000776 | E32: NEBILOC CCB TAB 5/5MG,PHL,3X10 | F32: FG-ROW | G32: Z_TABLET | H32: CT00982 | I32: 10 | J32: Bl | K32: 36729 | L32: =K32*I32 -> 367290 | M32: 0.28795918 | N32: =+K32*M32 -> 10576.453 | O32: 109.26667 | P32: =+K32*O32 -> 4013255.4
B33: 26 | C33: 1020 | D33: 5000987 | E33: ROSUFEN TAB 10/160MG,PHL,3X10 | F33: FG-ROW | G33: Z_TABLET | H33: CT00972 | I33: 10 | J33: Bl | K33: 19257 | L33: =K33*I33 -> 192570 | M33: 0.40052083 | N33: =+K33*M33 -> 7712.8297 | O33: 149.24833 | P33: =+K33*O33 -> 2874075.2
B34: 27 | C34: 1020 | D34: 5004170 | E34: APLEV M TAB 10/5MG,YEM,3X10'S | F34: FG-ROW | G34: Z_TABLET | H34: CT03532 | I34: 10 | J34: Bl | K34: 77619 | L34: =K34*I34 -> 776190 | M34: 0.30673913 | N34: =+K34*M34 -> 23808.785 | O34: 22.35 | P34: =+K34*O34 -> 1734784.6
B35: 28 | C35: 1020 | D35: 5006390 | E35: DAPAGLIFLOZIN+METFORMINHCLERTAB10/1000MG | F35: FG-ROW | G35: Z_TABLET | H35: CT03202 | I35: 1 | J35: NOS | K35: 192720 | L35: =K35*I35 -> 192720 | M35: 0.24566667 | N35: =+K35*M35 -> 47344.88 | O35: 29.8 | P35: =+K35*O35 -> 5743056
B36: 29 | C36: 1020 | D36: 5000011 | E36: RIDMAL TAB 80/640MG,FA,1X6 | F36: FG-ROW | G36: Z_TABLET | H36: CT02912 | I36: 6 | J36: Bl | K36: 65091 | L36: =K36*I36 -> 390546 | M36: 0.42304167 | N36: =+K36*M36 -> 27536.205 | O36: 268.55015 | P36: =+K36*O36 -> 17480198
B37: 30 | C37: 1020 | D37: 5006390 | E37: DAPAGLIFLOZIN+METFORMINHCLERTAB10/1000MG | F37: FG-ROW | G37: Z_TABLET | H37: CT03172 | I37: 1 | J37: NOS | K37: 193220 | L37: =K37*I37 -> 193220 | M37: 0.24566667 | N37: =+K37*M37 -> 47467.713 | O37: 29.8 | P37: =+K37*O37 -> 5757956
B38: 31 | C38: 1020 | D38: 5001440 | E38: AMADAY TAB 10MG,IRQ,2X14 | F38: FG-ROW | G38: Z_TABLET | H38: CT03542 | I38: 14 | J38: Bl | K38: 97900 | L38: =K38*I38 -> 1370600 | M38: 0.37334694 | N38: =+K38*M38 -> 36550.665 | O38: 13.0375 | P38: =+K38*O38 -> 1276371.2
B39: 32 | C39: 1020 | D39: 5002555 | E39: TIBAN TAB 20MG,IRQ,3X10 | F39: FG-ROW | G39: Z_TABLET | H39: CT03732 | I39: 10 | J39: Bl | K39: 39615 | L39: =K39*I39 -> 396150 | M39: 0.34177083 | N39: =+K39*M39 -> 13539.252 | O39: 123.42167 | P39: =+K39*O39 -> 4889349.3
... B83: 78 | C83: 1020 | D83: 5001045 | E83: KAMAGRA CT 100MG,G.EXP,1X4,STW/LIM | F83: FG-ROW | G83: Z_TABLET | H83: CT02522 | I83: 4 | J83: Bl | K83: 23669 | L83: =K83*I83 -> 94676 | M83: 0.23882105 | N83: =+K83*M83 -> 5652.6555 | O83: 12.499998 | P83: =+K83*O83 -> 295862.45
K84: =SUM(K28:K83) -> 2364178 | L84: =SUM(L28:L83) -> 18678203 | N84: =SUM(N28:N83) -> 872141.72 | P84: =SUM(P28:P83) -> 1.413072e+08
...

Sheet CKT
B2: CHIKALTHANA PLANT
B3: PRODUCTION DETAILS FOR THE MONTH OF APR-2022
B4: Sr. No. | C4: Plant | D4: Material code | E4: Material description | F4: Material Group | G4: Material Class | H4: Batch No | I4: Pack size | J4: Unit | K4: Prodn. Qty. in packs | L4: Qty. in Nos. | M4: DPCO Rate | N4: DPCO Value | O4: VOP Rate | P4: VOP
B5: 1 | C5: 1030 | D5: 5002418 | E5: APCOSULE CAP,RUS/KGZ,100 | F5: FG-ROW | G5: Z_CAPSULE | H5: CK00692 | I5: 100 | J5: BT | K5: 4926 | L5: =K5*I5 -> 492600 | M5: 6 | N5: =+K5*M5 -> 29556 | O5: 155.01382 | P5: =+K5*O5 -> 763598.08
B6: 2 | C6: 1030 | D6: 5002418 | E6: APCOSULE CAP,RUS/KGZ,100 | F6: FG-ROW | G6: Z_CAPSULE | H6: CK00682 | I6: 100 | J6: BT | K6: 6901 | L6: =K6*I6 -> 690100 | M6: 6 | N6: =+K6*M6 -> 41406 | O6: 155.01382 | P6: =+K6*O6 -> 1069750.4
B7: 3 | C7: 1030 | D7: 5002418 | E7: APCOSULE CAP,RUS/KGZ,100 | F7: FG-ROW | G7: Z_CAPSULE | H7: CK00672 | I7: 100 | J7: BT | K7: 6891 | L7: =K7*I7 -> 689100 | M7: 6 | N7: =+K7*M7 -> 41346 | O7: 155.01382 | P7: =+K7*O7 -> 1068200.2
B8: 4 | C8: 1030 | D8: 5002418 | E8: APCOSULE CAP,RUS/KGZ,100 | F8: FG-ROW | G8: Z_CAPSULE | H8: CK00662 | I8: 100 | J8: BT | K8: 6909 | L8: =K8*I8 -> 690900 | M8: 6 | N8: =+K8*M8 -> 41454 | O8: 155.01382 | P8: =+K8*O8 -> 1070990.5
K9: =SUM(K5:K8) -> 25627 | L9: =SUM(L5:L8) -> 2562700 | N9: =SUM(N5:N8) -> 153762 | P9: =SUM(P5:P8) -> 3972539.2
B10: 5 | C10: 1030 | D10: 5000141 | E10: SUPREME SUSP LIQUID,IRQ,100ML | F10: FG-ROW | G10: Z_SUSPENSION | H10: CK00882 | I10: 1 | J10: BT | K10: 24540 | L10: =K10*I10 -> 24540 | M10: 1.87 | N10: =+K10*M10 -> 45889.8 | O10: 23.163322 | P10: =+K10*O10 -> 568427.92
B11: 6 | C11: 1030 | D11: 5002516 | E11: ZAHA SUSPENSION,ZMB/UGA/KEN/GHA/SLK,15ML | F11: FG-ROW | G11: Z_SUSPENSION | H11: CK00842 | I11: 1 | J11: BT | K11: 65265 | L11: =K11*I11 -> 65265 | M11: 1.332 | N11: =+K11*M11 -> 86932.98 | O11: 55.837698 | P11: =+K11*O11 -> 3644247.4
B12: 7 | C12: 1030 | D12: 5002516 | E12: ZAHA SUSPENSION,ZMB/UGA/KEN/GHA/SLK,15ML | F12: FG-ROW | G12: Z_SUSPENSION | H12: CK00832 | I12: 1 | J12: BT | K12: 64833 | L12: =K12*I12 -> 64833 | M12: 1.332 | N12: =+K12*M12 -> 86357.556 | O12: 55.837698 | P12: =+K12*O12 -> 3620125.5
B13: 8 | C13: 1030 | D13: 5002516 | E13: ZAHA SUSPENSION,ZMB/UGA/KEN/GHA/SLK,15ML | F13: FG-ROW | G13: Z_SUSPENSION | H13: CK00822 | I13: 1 | J13: BT | K13: 64935 | L13: =K13*I13 -> 64935 | M13: 1.332 | N13: =+K13*M13 -> 86493.42 | O13: 55.837698 | P13: =+K13*O13 -> 3625820.9
B14: 9 | C14: 1030 | D14: 5001441 | E14: ZOCIN SUSP 200MG/5ML,G.EXP,15ML | F14: FG-ROW | G14: Z_SUSPENSION | H14: CK00602 | I14: 1 | J14: BT | K14: 32669 | L14: =K14*I14 -> 32669 | M14: 0.71 | N14: =+K14*M14 -> 23194.99 | O14: 180.41966 | P14: =+K14*O14 -> 5894129.8
B15: 10 | C15: 1030 | D15: 5001441 | E15: ZOCIN SUSP 200MG/5ML,G.EXP,15ML | F15: FG-ROW | G15: Z_SUSPENSION | H15: CK00592 | I15: 1 | J15: BT | K15: 32453 | L15: =K15*I15 -> 32453 | M15: 0.71 | N15: =+K15*M15 -> 23041.63 | O15: 180.41966 | P15: =+K15*O15 -> 5855159.2
B16: 11 | C16: 1030 | D16: 5001101 | E16: APFLU SYRUP,ZMB/UGA/KEN,100ML | F16: FG-ROW | G16: Z_SYRUP | H16: CK00902 | I16: 1 | J16: BT | K16: 24680 | L16: =K16*I16 -> 24680 | M16: 1.62 | N16: =+K16*M16 -> 39981.6 | O16: 45.894 | P16: =+K16*O16 -> 1132663.9
B17: 12 | C17: 1030 | D17: 5001101 | E17: APFLU SYRUP,ZMB/UGA/KEN,100ML | F17: FG-ROW | G17: Z_SYRUP | H17: CK00812 | I17: 1 | J17: BT | K17: 24560 | L17: =K17*I17 -> 24560 | M17: 1.62 | N17: =+K17*M17 -> 39787.2 | O17: 45.894 | P17: =+K17*O17 -> 1127156.6
B18: 13 | C18: 1030 | D18: 5001101 | E18: APFLU SYRUP,ZMB/UGA/KEN,100ML | F18: FG-ROW | G18: Z_SYRUP | H18: CK00802 | I18: 1 | J18: BT | K18: 24620 | L18: =K18*I18 -> 24620 | M18: 1.62 | N18: =+K18*M18 -> 39884.4 | O18: 45.894 | P18: =+K18*O18 -> 1129910.3
B19: 14 | C19: 1030 | D19: 5001101 | E19: APFLU SYRUP,ZMB/UGA/KEN,100ML | F19: FG-ROW | G19: Z_SYRUP | H19: CK00792 | I19: 1 | J19: BT | K19: 24620 | L19: =K19*I19 -> 24620 | M19: 1.62 | N19: =+K19*M19 -> 39884.4 | O19: 45.894 | P19: =+K19*O19 -> 1129910.3
B20: 15 | C20: 1030 | D20: 5001151 | E20: DYLDES SYRUP 0.50MG/ML,FA,60ML | F20: FG-ROW | G20: Z_SYRUP | H20: CK00862 | I20: 1 | J20: BT | K20: 13920 | L20: =K20*I20 -> 13920 | M20: 1.4878351 | N20: =+K20*M20 -> 20710.664 | O20: 183.5233 | P20: =+K20*O20 -> 2554644.3
B21: 16 | C21: 1030 | D21: 8000263 | E21: DYLDES SYRUP,FA,60ML | F21: FG-ROW | G21: Z_SYRUP | H21: CK00862 | I21: 1 | J21: BT | K21: 2550 | L21: =K21*I21 -> 2550 | M21: 1.39 | N21: =+K21*M21 -> 3544.5 | O21: 21.04625 | P21: =+K21*O21 -> 53667.937
... B34: 29 | C34: 1030 | D34: 5001105 | E34: FEDATE SYRUP,ZMB/GHA/UGA/KEN,200ML | F34: FG-ROW | G34: Z_SYRUP | H34: CK00612 | I34: 1 | J34: BT | K34: 9873 | L34: =K34*I34 -> 9873 | M34: 2.06 | N34: =+K34*M34 -> 20338.38 | O34: 83.985 | P34: =+K34*O34 -> 829183.91
K35: =SUM(K10:K34) -> 767230 | L35: =SUM(L10:L34) -> 767230 | N35: =SUM(N10:N34) -> 1182218.6 | P35: =SUM(P10:P34) -> 51724417
J37: Total | K37: =K35+K9 -> 792857 | L37: =L35+L9 -> 3329930 | N37: =N35+N9 -> 1335980.6 | P37: =P35+P9 -> 55696956

Sheet CML
B2: CML
B3: PRODUCTION DETAILS FOR THE MONTH OF APR-2022
B4: Sr. No. | C4: Plant Code | D4: Material code | E4: Material description | F4: Material Group | G4: Material Class | H4: Batch No | I4: Pack size | J4: Unit | K4: Prodn. Qty. in packs | L4: Qty. in Nos. | M4: DPCO Rate | N4: DPCO Value | O4: VOP Rate | P4: VOP | Q4: Plant Name
B5: 1 | C5: 5070 | D5: 5000136 | E5: APMOX CAP 250MG,IRQ,10X10 | F5: FG-ROW | G5: Z_CAPSULE | H5: MB0022C | I5: 10 | J5: Bl | K5: 58800 | L5: =K5*I5 -> 588000 | M5: 0.6374 | N5: =+K5*M5 -> 37479.12 | O5: 18.625 | P5: =+K5*O5 -> 1095150 | Q5: CMD-MR-CEPHA & BETA
B6: 2 | C6: 5070 | D6: 5000216 | E6: SIPRAX CAP 200MG,G.EXP,1X6 | F6: FG-ROW | G6: Z_CAPSULE | H6: MB0012C | I6: 6 | J6: Bl | K6: 48600 | L6: =K6*I6 -> 291600 | M6: 0.5247 | N6: =+K6*M6 -> 25500.42 | O6: 44.7 | P6: =+K6*O6 -> 2172420 | Q6: CMD-MR-CEPHA & BETA
B7: 3 | C7: 5070 | D7: 5000217 | E7: SIPRAX CAP 400MG,G. EXP,1X6 | F7: FG-ROW | G7: Z_CAPSULE | H7: MB0032B | I7: 6 | J7: Bl | K7: 65000 | L7: =K7*I7 -> 390000 | M7: 0.5247 | N7: =+K7*M7 -> 34105.5 | O7: 72.435125 | P7: =+K7*O7 -> 4708283.1 | Q7: CMD-MR-CEPHA & BETA
K8: =SUM(K5:K7) -> 172400 | L8: =SUM(L5:L7) -> 1269600 | N8: =SUM(N5:N7) -> 97085.04 | P8: =SUM(P5:P7) -> 7975853.1
B9: 4 | C9: 5051 | D9: 5501520 | E9: AQUREA CREAM 10,100GM | F9: FG-Domestic | G9: Z_CREAM | H9: E496 | I9: 1 | J9: JAR | K9: 2916 | L9: =K9*I9 -> 2916 | M9: 3.5591837 | N9: =+K9*M9 -> 10378.58 | O9: 128.14 | P9: =+K9*O9 -> 373656.24 | Q9: CMD_SHEFA
B10: 5 | C10: 5051 | D10: 8001300 | E10: AQUREA CREAM 10,20GM,PS | F10: FG-Domestic | G10: Z_CREAM | H10: E496 | I10: 1 | J10: JAR | K10: 9920 | L10: =K10*I10 -> 9920 | M10: 1.0465306 | N10: =+K10*M10 -> 10381.584 | O10: 0 | P10: =+K10*O10 -> 0 | Q10: CMD_SHEFA
B11: 6 | C11: 5014 | D11: 5500069 | E11: TALIMUS LS OINTMENT,5GM | F11: FG-Domestic | G11: Z_CREAM | H11: B667 | I11: 1 | J11: Tb | K11: 19980 | L11: =K11*I11 -> 19980 | M11: 0.713 | N11: =+K11*M11 -> 14245.74 | O11: 173.31296 | P11: =+K11*O11 -> 3462793 | Q11: CMD_BRASSICA
B12: 7 | C12: 5014 | D12: 5500292 | E12: TALIMUS OINTMENT,5GM | F12: FG-Domestic | G12: Z_CREAM | H12: B666 | I12: 1 | J12: Tb | K12: 28720 | L12: =K12*I12 -> 28720 | M12: 0.71 | N12: =+K12*M12 -> 20391.2 | O12: 219.21019 | P12: =+K12*O12 -> 6295716.8 | Q12: CMD_BRASSICA
